Workbook

Sheet readme
R6: Variables/traits | S6: Description | T6: Unit | U6: comments
R7: AvgHeight | T7: cm
R8: AvgNode | T8: cm
R9: Biomass | S9: total of plants in 1 or 2m less 5 plants | T9: Kg | U9: 2m just in H4
R10: Biomass5pl | S10: (green leaf+yellow leaf+stem+reproductive) of 5 plants that was used for partioning | T10: Kg
R11: biomasstotal | S11: total biomass in 1/2m | T11: Kg
R12: DAS | S12: Days after sowing | T12: -
R13: Date | T13: m/d/y
R14: DOY | S14: Days of the Year | T14: day
R15: GreenBiomass | S15: Green leaf biomass | T15: kg.ha
R16: GreenPartition5 | S16: green leaf weight of 5 plants | T16: Kg
R17: HI | S17: Harvest Index
R18: linear | S18: how much was collected per plot | T18: m
R19: Plot
R20: Population | T20: plants/ha
R21: POROgsw | T21: mol+1m-2s-1
R22: Port | S22: connection port | T22: m³/m³ Water Content
R23: Rep | S23: Replication | T23: -
R24: RepBiomass | S24: Reproductive biomass | T24: kg.ha
R25: Reprod Partition5 | S25: reproductive weight of 5 plants | T25: Kg
R26: Row space | T26: m
R27: seedBiomass | S27: total seeds of 5 plants | T27: kg.ha
R28: SeedTotalBiomass | S28: total seeds of the total biomass | T28: kg.ha
R29: Stem Partition5 | S29: stem weight of 5 plants | T29: Kg
R30: StemBiomass | S30: Stem biomass | T30: kg.ha
R31: TotalBiomass | T31: Kg.ha
R32: TotalSampleArea | S32: harvested area | T32: m2
R33: YellowBiomass | S33: Yellow leaf biomass | T33: kg.ha
B34: I replaced the last harvest called 4 to final, to refer to the last one when yield was determined. | R34: YellowPartition5 | S34: yellow leaf weight of 5 plants | T34: Kg
R35: Yield | S35: Final yield | T35: kg.ha bu.ac
R40: weather data from planting date until september 30 for both years.
R42: Plots removed from sarec 2025 outliers from the field: 501-502-503-701-702-703-704-705

Sheet genotypes
E2: Genotype24
E3: P42A84E | F3: 4-Early
E4: P48A14E | F4: 4-Early
E5: P52A14SE | F5: 5-Early
E6: R19C-1012 | F6: 4-Early
E7: R18-14502 | F7: 4-Late
E8: R18C-13665 | F8: 4-Late
E9: R19-46252 | F9: 5-Early
E10: R19-45980 | F10: 5-Early
E11: PI471938
E12: PI548431
E13: PI603457A
E14: PI507408

Sheet 2024-H2
C6: Rainfed | I6: Irrigated
C8: Plot number
A10: Range 12 | B10: REP1 | C10: 12 | D10: REP2 | E10: 24 | F10: REP3 | G10: 36 | H10: REP1 | I10: 48 | J10: REP2 | K10: 60 | L10: REP3 | M10: 72
A11: Range 11 | C11: 11 | E11: 23 | G11: 35 | I11: 47 | K11: 59 | M11: 71
A12: Range 10 | C12: 10 | E12: 22 | G12: 34 | I12: 46 | K12: 58 | M12: 70
A13: Range 9 | C13: 9 | E13: 21 | G13: 33 | I13: 45 | K13: 57 | M13: 69
A14: Range 8 | C14: 8 | E14: 20 | G14: 32 | I14: 44 | K14: 56 | M14: 68
A15: Range 7 | C15: 7 | E15: 19 | G15: 31 | I15: 43 | K15: 55 | M15: 67
A16: Range 6 | C16: 6 | E16: 18 | G16: 30 | I16: 42 | K16: 54 | M16: 66
A17: Range 5 | C17: 5 | E17: 17 | G17: 29 | I17: 41 | K17: 53 | M17: 65
A18: Range 4 | C18: 4 | E18: 16 | G18: 28 | I18: 40 | K18: 52 | M18: 64
A19: Range 3 | C19: 3 | E19: 15 | G19: 27 | I19: 39 | K19: 51 | M19: 63
A20: Range 2 | C20: 2 | E20: 14 | G20: 26 | I20: 38 | K20: 50 | M20: 62
A21: Range 1 | C21: 1 | E21: 13 | G21: 25 | I21: 37 | K21: 49 | M21: 61
C23: Col 1 | E23: Col 2 | G23: Col 3 | I23: Col 4 | K23: Col 5 | M23: Col 6
A34: Rainfed
A36: Range 12 | C36: REP1 | D36: 12 | E36: PI567488B | F36: REP2 | G36: 24 | H36: P52A14SE | I36: REP3 | J36: 36 | K36: R19-46252
A37: Range 11 | D37: 11 | E37: PI424397 | G37: 23 | H37: R18C-13665 | J37: 35 | K37: R18-14502
A38: Range 10 | D38: 10 | E38: PI377574 | G38: 22 | H38: PI567488B | J38: 34 | K38: R18C-13665
A39: Range 9 | D39: 9 | E39: PI398245 | G39: 21 | H39: P42A84E | J39: 33 | K39: R19C-1012
A40: Range 8 | D40: 8 | E40: R19-45980 | G40: 20 | H40: PI424397 | J40: 32 | K40: P52A14SE
A41: Range 7 | D41: 7 | E41: R19-46252 | G41: 19 | H41: R18-14502 | J41: 31 | K41: PI377574
A42: Range 6 | D42: 6 | E42: R18C-13665 | G42: 18 | H42: R19C-1012 | J42: 30 | K42: PI424397
A43: Range 5 | D43: 5 | E43: R18-14502 | G43: 17 | H43: R19-46252 | J43: 29 | K43: PI567488B
A44: Range 4 | D44: 4 | E44: R19C-1012 | G44: 16 | H44: P48A14E | J44: 28 | K44: PI398245
A45: Range 3 | D45: 3 | E45: P52A14SE | G45: 15 | H45: PI398245 | J45: 27 | K45: R19-45980
A46: Range 2 | D46: 2 | E46: P48A14E | G46: 14 | H46: R19-45980 | J46: 26 | K46: P42A84E
A47: Range 1 | D47: 1 | E47: P42A84E | G47: 13 | H47: PI377574 | J47: 25 | K47: P48A14E
D49: Col 1 | G49: Col 2 | J49: Col 3
A51: Irrigated
A53: Range 12 | C53: REP1 | D53: 48 | E53: PI567488B | F53: REP2 | G53: 60 | H53: P52A14SE | I53: REP3 | J53: 72 | K53: R19-46252
A54: Range 11 | D54: 47 | E54: PI424397 | G54: 59 | H54: R18C-13665 | J54: 71 | K54: R18-14502
A55: Range 10 | D55: 46 | E55: PI377574 | G55: 58 | H55: PI567488B | J55: 70 | K55: R18C-13665
A56: Range 9 | D56: 45 | E56: PI398245 | G56: 57 | H56: P42A84E | J56: 69 | K56: R19C-1012
A57: Range 8 | D57: 44 | E57: R19-45980 | G57: 56 | H57: PI424397 | J57: 68 | K57: P52A14SE
A58: Range 7 | D58: 43 | E58: R19-46252 | G58: 55 | H58: R18-14502 | J58: 67 | K58: PI377574
A59: Range 6 | D59: 42 | E59: R18C-13665 | G59: 54 | H59: R19C-1012 | J59: 66 | K59: PI424397
A60: Range 5 | D60: 41 | E60: R18-14502 | G60: 53 | H60: R19-46252 | J60: 65 | K60: PI567488B
A61: Range 4 | D61: 40 | E61: R19C-1012 | G61: 52 | H61: P48A14E | J61: 64 | K61: PI398245
A62: Range 3 | D62: 39 | E62: P52A14SE | G62: 51 | H62: PI398245 | J62: 63 | K62: R19-45980
...

Sheet 2024-H3
C6: Rainfed | I6: Irrigated
C8: Plot number
A10: Range 12 | B10: REP1 | C10: 12 | D10: REP2 | E10: 24 | F10: REP3 | G10: 36 | H10: REP1 | I10: 48 | J10: REP2 | K10: 60 | L10: REP3 | M10: 72
A11: Range 11 | C11: 11 | E11: 23 | G11: 35 | I11: 47 | K11: 59 | M11: 71
A12: Range 10 | C12: 10 | E12: 22 | G12: 34 | I12: 46 | K12: 58 | M12: 70
A13: Range 9 | C13: 9 | E13: 21 | G13: 33 | I13: 45 | K13: 57 | M13: 69
A14: Range 8 | C14: 8 | E14: 20 | G14: 32 | I14: 44 | K14: 56 | M14: 68
A15: Range 7 | C15: 7 | E15: 19 | G15: 31 | I15: 43 | K15: 55 | M15: 67
A16: Range 6 | C16: 6 | E16: 18 | G16: 30 | I16: 42 | K16: 54 | M16: 66
A17: Range 5 | C17: 5 | E17: 17 | G17: 29 | I17: 41 | K17: 53 | M17: 65
A18: Range 4 | C18: 4 | E18: 16 | G18: 28 | I18: 40 | K18: 52 | M18: 64
A19: Range 3 | C19: 3 | E19: 15 | G19: 27 | I19: 39 | K19: 51 | M19: 63
A20: Range 2 | C20: 2 | E20: 14 | G20: 26 | I20: 38 | K20: 50 | M20: 62
A21: Range 1 | C21: 1 | E21: 13 | G21: 25 | I21: 37 | K21: 49 | M21: 61
C23: Col 1 | E23: Col 2 | G23: Col 3 | I23: Col 4 | K23: Col 5 | M23: Col 6
A34: Rainfed
A36: Range 12 | C36: REP1 | D36: 12 | E36: PI567488B | F36: REP2 | G36: 24 | H36: P52A14SE | I36: REP3 | J36: 36 | K36: R19-46252
A37: Range 11 | D37: 11 | E37: PI424397 | G37: 23 | H37: R18C-13665 | J37: 35 | K37: R18-14502
A38: Range 10 | D38: 10 | E38: PI377574 | G38: 22 | H38: PI567488B | J38: 34 | K38: R18C-13665
A39: Range 9 | D39: 9 | E39: PI398245 | G39: 21 | H39: P42A84E | J39: 33 | K39: R19C-1012
A40: Range 8 | D40: 8 | E40: R19-45980 | G40: 20 | H40: PI424397 | J40: 32 | K40: P52A14SE
A41: Range 7 | D41: 7 | E41: R19-46252 | G41: 19 | H41: R18-14502 | J41: 31 | K41: PI377574
A42: Range 6 | D42: 6 | E42: R18C-13665 | G42: 18 | H42: R19C-1012 | J42: 30 | K42: PI424397
A43: Range 5 | D43: 5 | E43: R18-14502 | G43: 17 | H43: R19-46252 | J43: 29 | K43: PI567488B
A44: Range 4 | D44: 4 | E44: R19C-1012 | G44: 16 | H44: P48A14E | J44: 28 | K44: PI398245
A45: Range 3 | D45: 3 | E45: P52A14SE | G45: 15 | H45: PI398245 | J45: 27 | K45: R19-45980
A46: Range 2 | D46: 2 | E46: P48A14E | G46: 14 | H46: R19-45980 | J46: 26 | K46: P42A84E
A47: Range 1 | D47: 1 | E47: P42A84E | G47: 13 | H47: PI377574 | J47: 25 | K47: P48A14E
D49: Col 1 | G49: Col 2 | J49: Col 3
A51: Irrigated
A53: Range 12 | C53: REP1 | D53: 48 | E53: PI567488B | F53: REP2 | G53: 60 | H53: P52A14SE | I53: REP3 | J53: 72 | K53: R19-46252
A54: Range 11 | D54: 47 | E54: PI424397 | G54: 59 | H54: R18C-13665 | J54: 71 | K54: R18-14502
A55: Range 10 | D55: 46 | E55: PI377574 | G55: 58 | H55: PI567488B | J55: 70 | K55: R18C-13665
A56: Range 9 | D56: 45 | E56: PI398245 | G56: 57 | H56: P42A84E | J56: 69 | K56: R19C-1012
A57: Range 8 | D57: 44 | E57: R19-45980 | G57: 56 | H57: PI424397 | J57: 68 | K57: P52A14SE
A58: Range 7 | D58: 43 | E58: R19-46252 | G58: 55 | H58: R18-14502 | J58: 67 | K58: PI377574
A59: Range 6 | D59: 42 | E59: R18C-13665 | G59: 54 | H59: R19C-1012 | J59: 66 | K59: PI424397
A60: Range 5 | D60: 41 | E60: R18-14502 | G60: 53 | H60: R19-46252 | J60: 65 | K60: PI567488B
A61: Range 4 | D61: 40 | E61: R19C-1012 | G61: 52 | H61: P48A14E | J61: 64 | K61: PI398245
A62: Range 3 | D62: 39 | E62: P52A14SE | G62: 51 | H62: PI398245 | J62: 63 | K62: R19-45980
...

Sheet 2024-H4
C6: Rainfed | I6: Irrigated
C8: Plot number
A10: Range 12 | B10: REP1 | C10: 12 | D10: REP2 | E10: 24 | F10: REP3 | G10: 36 | H10: REP1 | I10: 48 | J10: REP2 | K10: 60 | L10: REP3 | M10: 72
A11: Range 11 | C11: 11 | E11: 23 | G11: 35 | I11: 47 | K11: 59 | M11: 71
A12: Range 10 | C12: 10 | E12: 22 | G12: 34 | I12: 46 | K12: 58 | M12: 70
A13: Range 9 | C13: 9 | E13: 21 | G13: 33 | I13: 45 | K13: 57 | M13: 69
A14: Range 8 | C14: 8 | E14: 20 | G14: 32 | I14: 44 | K14: 56 | M14: 68
A15: Range 7 | C15: 7 | E15: 19 | G15: 31 | I15: 43 | K15: 55 | M15: 67
A16: Range 6 | C16: 6 | E16: 18 | G16: 30 | I16: 42 | K16: 54 | M16: 66
A17: Range 5 | C17: 5 | E17: 17 | G17: 29 | I17: 41 | K17: 53 | M17: 65
A18: Range 4 | C18: 4 | E18: 16 | G18: 28 | I18: 40 | K18: 52 | M18: 64
A19: Range 3 | C19: 3 | E19: 15 | G19: 27 | I19: 39 | K19: 51 | M19: 63
A20: Range 2 | C20: 2 | E20: 14 | G20: 26 | I20: 38 | K20: 50 | M20: 62
A21: Range 1 | C21: 1 | E21: 13 | G21: 25 | I21: 37 | K21: 49 | M21: 61
C23: Col 1 | E23: Col 2 | G23: Col 3 | I23: Col 4 | K23: Col 5 | M23: Col 6
A34: Rainfed
A36: Range 12 | C36: REP1 | D36: 12 | E36: PI567488B | F36: REP2 | G36: 24 | H36: P52A14SE | I36: REP3 | J36: 36 | K36: R19-46252
A37: Range 11 | D37: 11 | E37: PI424397 | G37: 23 | H37: R18C-13665 | J37: 35 | K37: R18-14502
A38: Range 10 | D38: 10 | E38: PI377574 | G38: 22 | H38: PI567488B | J38: 34 | K38: R18C-13665
A39: Range 9 | D39: 9 | E39: PI398245 | G39: 21 | H39: P42A84E | J39: 33 | K39: R19C-1012
A40: Range 8 | D40: 8 | E40: R19-45980 | G40: 20 | H40: PI424397 | J40: 32 | K40: P52A14SE
A41: Range 7 | D41: 7 | E41: R19-46252 | G41: 19 | H41: R18-14502 | J41: 31 | K41: PI377574
A42: Range 6 | D42: 6 | E42: R18C-13665 | G42: 18 | H42: R19C-1012 | J42: 30 | K42: PI424397
A43: Range 5 | D43: 5 | E43: R18-14502 | G43: 17 | H43: R19-46252 | J43: 29 | K43: PI567488B
A44: Range 4 | D44: 4 | E44: R19C-1012 | G44: 16 | H44: P48A14E | J44: 28 | K44: PI398245
A45: Range 3 | D45: 3 | E45: P52A14SE | G45: 15 | H45: PI398245 | J45: 27 | K45: R19-45980
A46: Range 2 | D46: 2 | E46: P48A14E | G46: 14 | H46: R19-45980 | J46: 26 | K46: P42A84E
A47: Range 1 | D47: 1 | E47: P42A84E | G47: 13 | H47: PI377574 | J47: 25 | K47: P48A14E
D49: Col 1 | G49: Col 2 | J49: Col 3
A51: Irrigated
A53: Range 12 | C53: REP1 | D53: 48 | E53: PI567488B | F53: REP2 | G53: 60 | H53: P52A14SE | I53: REP3 | J53: 72 | K53: R19-46252
A54: Range 11 | D54: 47 | E54: PI424397 | G54: 59 | H54: R18C-13665 | J54: 71 | K54: R18-14502
A55: Range 10 | D55: 46 | E55: PI377574 | G55: 58 | H55: PI567488B | J55: 70 | K55: R18C-13665
A56: Range 9 | D56: 45 | E56: PI398245 | G56: 57 | H56: P42A84E | J56: 69 | K56: R19C-1012
A57: Range 8 | D57: 44 | E57: R19-45980 | G57: 56 | H57: PI424397 | J57: 68 | K57: P52A14SE
A58: Range 7 | D58: 43 | E58: R19-46252 | G58: 55 | H58: R18-14502 | J58: 67 | K58: PI377574
A59: Range 6 | D59: 42 | E59: R18C-13665 | G59: 54 | H59: R19C-1012 | J59: 66 | K59: PI424397
A60: Range 5 | D60: 41 | E60: R18-14502 | G60: 53 | H60: R19-46252 | J60: 65 | K60: PI567488B
A61: Range 4 | D61: 40 | E61: R19C-1012 | G61: 52 | H61: P48A14E | J61: 64 | K61: PI398245
A62: Range 3 | D62: 39 | E62: P52A14SE | G62: 51 | H62: PI398245 | J62: 63 | K62: R19-45980
...

Sheet all
A1: Year | B1: Harvest | C1: Genotype | D1: Treatment | E1: Rep | F1: Plot | G1: Date | H1: DOY | I1: DAP | J1: Location | K1: Population | L1: GreenPartition5 | M1: YellowPartition5 | N1: StemPartition5 | O1: ReprodPartition5 | P1: SeedPartition5 | Q1: SeedTB | R1: BiomassPartition5 | S1: Biomass_linear | T1: TotalBiomass_kg_ha | U1: linear | V1: RowSpace | W1: TotalSampleArea | X1: GreenBiomass | Y1: YellowBiomass | Z1: StemBiomass | AA1: ReprodBiomass | AB1: SeedBiomass | AC1: SeedTB_ha | AD1: yield_kg_ha | AE1: yield_combine | AF1: HI | AG1: yield_bu_ac | AH1: AvgHeight | AI1: AvgNode
A2: 2024 | B2: final | C2: P42A84E | D2: Rainfed | E2: 1 | F2: 1 | G2: 45572 | H2: 280 | J2: sarec | K2: 37100 | L2: 0 | M2: 1.6 | N2: 19.89 | O2: 54.3 | P2: 35.8 | Q2: 241.5 | R2: 111.59 | S2: 609.5 | T2: 3748.8512 | U2: 2 | V2: 0.914 | W2: 1.828 | X2: 0 | Y2: 79.141865 | Z2: 983.83231 | AA2: 2685.877 | AB2: 1770.7992 | AC2: 1485.3939 | AD2: 1516.9584 | AF2: 0.40464621 | AG2: 25.980093 | AH2: 48.006 | AI2: 13
A3: 2024 | B3: final | C3: P48A14E | D3: Rainfed | E3: 1 | F3: 2 | G3: 45566 | H3: 274 | J3: sarec | K3: 37100 | L3: 0 | M3: 0.6 | N3: 22.89 | O3: 76.3 | P3: 51.9 | Q3: 213.1 | R3: 151.69 | S3: 475.5 | T3: 3147.1007 | U3: 2 | V3: 0.914 | W3: 1.828 | X3: 0 | Y3: 18.922341 | Z3: 721.8873 | AA3: 2406.291 | AB3: 1636.7825 | AC3: 1410.4041 | AD3: 1449.6718 | AF3: 0.46063724 | AG3: 24.827712 | AH3: 54.9402 | AI3: 15.2
A4: 2024 | B4: final | C4: P52A14SE | D4: Rainfed | E4: 1 | F4: 3 | G4: 45572 | H4: 280 | J4: sarec | K4: 37100 | L4: 0 | M4: 1.6 | N4: 25.89 | O4: 63.3 | P4: 42.5 | Q4: 199 | R4: 133.29 | S4: 472.5 | T4: 3081.4551 | U4: 2 | V4: 0.914 | W4: 1.828 | X4: 0 | Y4: 54.30475 | Z4: 878.71873 | AA4: 2148.4317 | AB4: 1442.4699 | AC4: 1297.798 | AD4: 1321.116 | AF4: 0.4287312 | AG4: 22.626009 | AH4: 51.308 | AI4: 12
A5: 2024 | B5: final | C5: R19C-1012 | D5: Rainfed | E5: 1 | F5: 4 | G5: 45566 | H5: 274 | J5: sarec | K5: 37100 | L5: 0 | M5: 0 | N5: 35.89 | O5: 101.3 | P5: 66 | Q5: 199.1 | R5: 203.19 | S5: 480.5 | T5: 3379.0481 | U5: 2 | V5: 0.914 | W5: 1.828 | X5: 0 | Y5: 0 | Z5: 883.98599 | AA5: 2495.0622 | AB5: 1625.6081 | AC5: 1400.1425 | AD5: 1450.2188 | AF5: 0.42917969 | AG5: 24.837081 | AH5: 58.674 | AI5: 19.2
A6: 2024 | B6: final | C6: R18-14502 | D6: Rainfed | E6: 1 | F6: 5 | G6: 45566 | H6: 274 | J6: sarec | K6: 37100 | L6: 0 | M6: 0 | N6: 22.89 | O6: 74.3 | P6: 49.6 | Q6: 0 | R6: 146.79 | S6: 0 | T6: 531.67396 | U6: 2 | V6: 0.914 | W6: 1.828 | X6: 0 | Y6: 0 | Z6: 125.21882 | AA6: 406.45514 | AB6: 271.33479 | AC6: 0 | AD6: 271.33479 | AF6: 0.51034057 | AG6: 4.6469982 | AH6: 64.262 | AI6: 19
A7: 2024 | B7: final | C7: R18C-13665 | D7: Rainfed | E7: 1 | F7: 6 | G7: 45576 | H7: 284 | J7: sarec | K7: 37100 | L7: 0 | M7: 0 | N7: 0 | O7: 0 | P7: 0 | Q7: 472.9 | R7: 0 | S7: 975.5 | T7: 5336.4333 | U7: 2 | V7: 0.914 | W7: 1.828 | X7: 0 | Y7: 0 | Z7: 0 | AA7: 0 | AB7: 0 | AC7: 2586.9803 | AD7: 2586.9803 | AF7: 0.48477704 | AG7: 44.305755
A8: 2024 | B8: final | C8: R19-46252 | D8: Rainfed | E8: 1 | F8: 7 | G8: 45576 | H8: 284 | J8: sarec | K8: 37100 | L8: 0 | M8: 0 | N8: 0 | O8: 0 | P8: 0 | Q8: 323.9 | R8: 0 | S8: 762.5 | T8: 4171.2254 | U8: 2 | V8: 0.914 | W8: 1.828 | X8: 0 | Y8: 0 | Z8: 0 | AA8: 0 | AB8: 0 | AC8: 1771.8818 | AD8: 1771.8818 | AF8: 0.42478689 | AG8: 30.346022
A9: 2024 | B9: final | C9: R19-45980 | D9: Rainfed | E9: 1 | F9: 8 | G9: 45572 | H9: 280 | J9: sarec | K9: 37100 | L9: 0 | M9: 0 | N9: 0 | O9: 0 | P9: 0 | Q9: 226.3 | R9: 0 | S9: 639.5 | T9: 3498.3589 | U9: 2 | V9: 0.914 | W9: 1.828 | X9: 0 | Y9: 0 | Z9: 0 | AA9: 0 | AB9: 0 | AC9: 1237.965 | AD9: 1237.965 | AF9: 0.35387021 | AG9: 21.201929
A10: 2024 | B10: final | C10: PI471938 | D10: Rainfed | E10: 1 | F10: 9 | G10: 45562 | H10: 270 | J10: sarec | K10: 37100 | L10: 0 | M10: 0 | N10: 23.89 | O10: 88.3 | P10: 44.1 | Q10: 130.1 | R10: 156.29 | S10: 275.5 | T10: 2120.8425 | U10: 2 | V10: 0.914 | W10: 1.828 | X10: 0 | Y10: 0 | Z10: 451.61713 | AA10: 1669.2253 | AB10: 833.66746 | AC10: 1001.5303 | AD10: 952.95405 | AF10: 0.44932807 | AG10: 16.320707 | AH10: 31.75 | AI10: 12.8
A11: 2024 | B11: final | C11: PI548431 | D11: Rainfed | E11: 1 | F11: 10 | G11: 45562 | H11: 270 | J11: sarec | K11: 37100 | L11: 0 | M11: 0 | N11: 29.89 | O11: 89.3 | P11: 50.4 | Q11: 106.1 | R11: 169.59 | S11: 301.5 | T11: 2301.3676 | U11: 2 | V11: 0.914 | W11: 1.828 | X11: 0 | Y11: 0 | Z11: 577.12793 | AA11: 1724.2397 | AB11: 973.14311 | AC11: 809.86767 | AD11: 856.12691 | AF11: 0.37200789 | AG11: 14.662403 | AH11: 48.768 | AI11: 14.6
A12: 2024 | B12: final | C12: PI603457A | D12: Rainfed | E12: 1 | F12: 11 | G12: 45562 | H12: 270 | J12: sarec | K12: 37100 | L12: 0 | M12: 27.6 | N12: 53.89 | O12: 105.3 | P12: 59 | Q12: 107.5 | R12: 245.79 | S12: 300.5 | T12: 2665.7002 | U12: 2 | V12: 0.914 | W12: 1.828 | X12: 0 | Y12: 393.88257 | Z12: 769.07 | AA12: 1502.7476 | AB12: 841.99536 | AC12: 953.61988 | AD12: 910.83151 | AF12: 0.34168565 | AG12: 15.599298 | AH12: 44.45 | AI12: 14.2
A13: 2024 | B13: final | C13: PI507408 | D13: Rainfed | E13: 1 | F13: 12 | G13: 45562 | H13: 270 | J13: sarec | K13: 37100 | L13: 0 | M13: 0 | N13: 0 | O13: 0 | P13: 0 | Q13: 274 | R13: 0 | S13: 612.5 | T13: 3350.6565 | U13: 2 | V13: 0.914 | W13: 1.828 | X13: 0 | Y13: 0 | Z13: 0 | AA13: 0 | AB13: 0 | AC13: 1498.9059 | AD13: 1498.9059 | AF13: 0.44734694 | AG13: 25.670917
A14: 2024 | B14: final | C14: PI548431 | D14: Rainfed | E14: 2 | F14: 13 | G14: 45562 | H14: 270 | J14: sarec | K14: 37100 | L14: 0 | M14: 0 | N14: 22.89 | O14: 67.3 | P14: 31 | Q14: 76.2 | R14: 121.19 | S14: 309.5 | T14: 2186.488 | U14: 2 | V14: 0.914 | W14: 1.828 | X14: 0 | Y14: 0 | Z14: 554.92526 | AA14: 1631.5627 | AB14: 751.53705 | AC14: 538.32111 | AD14: 586.43326 | AF14: 0.26820786 | AG14: 10.043512 | AH14: 56.896 | AI14: 15.8
A15: 2024 | B15: final | C15: R19-45980 | D15: Rainfed | E15: 2 | F15: 14 | G15: 45576 | H15: 284 | J15: sarec | K15: 37100 | L15: 0 | M15: 0 | N15: 0 | O15: 0 | P15: 0 | Q15: 301.1 | R15: 0 | S15: 723.5 | T15: 3957.8775 | U15: 2 | V15: 0.914 | W15: 1.828 | X15: 0 | Y15: 0 | Z15: 0 | AA15: 0 | AB15: 0 | AC15: 1647.1554 | AD15: 1647.1554 | AF15: 0.41617139 | AG15: 28.209902
A16: 2024 | B16: final | C16: PI471938 | D16: Rainfed | E16: 2 | F16: 15 | G16: 45562 | H16: 270 | J16: sarec | K16: 37100 | L16: 0 | M16: 1.6 | N16: 39.89 | O16: 168.3 | P16: 105.5 | Q16: 143.2 | R16: 315.29 | S16: 295.5 | T16: 2764.1685 | U16: 2 | V16: 0.914 | W16: 1.828 | X16: 0 | Y16: 21.081413 | Z16: 525.58597 | AA16: 2217.5011 | AB16: 1390.0557 | AC16: 1339.5226 | AD16: 1360.5033 | AF16: 0.4921926 | AG16: 23.300573 | AH16: 38.608 | AI16: 14.6
A17: 2024 | B17: final | C17: P48A14E | D17: Rainfed | E17: 2 | F17: 16 | G17: 45566 | H17: 274 | J17: sarec | K17: 37100 | L17: 0 | M17: 3.6 | N17: 26.89 | O17: 65.3 | P17: 43.2 | Q17: 255.9 | R17: 138.99 | S17: 662.5 | T17: 4148.1947 | U17: 2 | V17: 0.914 | W17: 1.828 | X17: 0 | Y17: 155.89833 | Z17: 1164.4739 | AA17: 2827.8225 | AB17: 1870.78 | AC17: 1602.2989 | AD17: 1636.2144 | AF17: 0.39444012 | AG17: 28.022523 | AH17: 57.404 | AI17: 14.2
A18: 2024 | B18: final | C18: R19-46252 | D18: Rainfed | E18: 2 | F18: 17 | G18: 45576 | H18: 284 | J18: sarec | K18: 37100 | L18: 0 | M18: 0 | N18: 0 | O18: 0 | P18: 0 | Q18: 262.9 | R18: 0 | S18: 663.5 | T18: 3629.6499 | U18: 2 | V18: 0.914 | W18: 1.828 | X18: 0 | Y18: 0 | Z18: 0 | AA18: 0 | AB18: 0 | AC18: 1438.1838 | AD18: 1438.1838 | AF18: 0.3962321 | AG18: 24.630964
A19: 2024 | B19: final | C19: R19C-1012 | D19: Rainfed | E19: 2 | F19: 18 | G19: 45566 | H19: 274 | J19: sarec | K19: 37100 | L19: 0 | M19: 0 | N19: 28.89 | O19: 68.3 | P19: 47.6 | Q19: 260.4 | R19: 144.79 | S19: 637.5 | T19: 4019.0919 | U19: 2 | V19: 0.914 | W19: 1.828 | X19: 0 | Y19: 0 | Z19: 1194.6863 | AA19: 2824.4056 | AB19: 1968.3998 | AC19: 1641.6808 | AD19: 1684.9015 | AF19: 0.41922443 | AG19: 28.85636 | AH19: 66.294 | AI19: 17.2
A20: 2024 | B20: final | C20: R18-14502 | D20: Rainfed | E20: 2 | F20: 19 | G20: 45566 | H20: 274 | J20: sarec | K20: 37100 | L20: 0 | M20: 0 | N20: 20.89 | O20: 68.3 | P20: 47.5 | Q20: 265.5 | R20: 136.69 | S20: 572.5 | T20: 3619.7484 | U20: 2 | V20: 0.914 | W20: 1.828 | X20: 0 | Y20: 0 | Z20: 847.81414 | AA20: 2771.9342 | AB20: 1927.7727 | AC20: 1678.6781 | AD20: 1712.2538 | AF20: 0.47303118 | AG20: 29.324807 | AH20: 61.722 | AI20: 16.4
A21: 2024 | B21: final | C21: PI603457A | D21: Rainfed | E21: 2 | F21: 20 | G21: 45562 | H21: 270 | J21: sarec | K21: 37100 | L21: 0 | M21: 0.6 | N21: 27.89 | O21: 55.3 | P21: 31.4 | Q21: 132.2 | R21: 115.19 | S21: 330.5 | T21: 2266.3567 | U21: 2 | V21: 0.914 | W21: 1.828 | X21: 0 | Y21: 16.228834 | Z21: 754.3703 | AA21: 1495.7575 | AB21: 849.30898 | AC21: 906.54267 | AD21: 894.96718 | AF21: 0.39489247 | AG21: 15.327599 | AH21: 40.386 | AI21: 15.2
A22: 2024 | B22: final | C22: P42A84E | D22: Rainfed | E22: 2 | F22: 21 | G22: 45576 | H22: 284 | J22: sarec | K22: 37100 | L22: 0 | M22: 0 | N22: 17.89 | O22: 92.3 | P22: 65.7 | Q22: 195.8 | R22: 175.89 | S22: 429.5 | T22: 2952.3523 | U22: 2 | V22: 0.914 | W22: 1.828 | X22: 0 | Y22: 0 | Z22: 479.3319 | AA22: 2473.0204 | AB22: 1760.319 | AC22: 1345.9152 | AD22: 1430.5252 | AF22: 0.48453742 | AG22: 24.499799 | AH22: 42.418 | AI22: 15
A23: 2024 | B23: final | C23: PI507408 | D23: Rainfed | E23: 2 | F23: 22 | G23: 45562 | H23: 270 | J23: sarec | K23: 37100 | L23: 0 | M23: 0 | N23: 0 | O23: 0 | P23: 0 | Q23: 331.3 | R23: 0 | S23: 679.5 | T23: 3717.1772 | U23: 2 | V23: 0.914 | W23: 1.828 | X23: 0 | Y23: 0 | Z23: 0 | AA23: 0 | AB23: 0 | AC23: 1812.3632 | AD23: 1812.3632 | AF23: 0.48756439 | AG23: 31.039324
A24: 2024 | B24: final | C24: R18C-13665 | D24: Rainfed | E24: 2 | F24: 23 | G24: 45576 | H24: 284 | J24: sarec | K24: 37100 | L24: 0 | M24: 0 | N24: 0 | O24: 0 | P24: 0 | Q24: 329.5 | R24: 0 | S24: 696.5 | T24: 3810.1751 | U24: 2 | V24: 0.914 | W24: 1.828 | X24: 0 | Y24: 0 | Z24: 0 | AA24: 0 | AB24: 0 | AC24: 1802.5164 | AD24: 1802.5164 | AF24: 0.47307968 | AG24: 30.870683
A25: 2024 | B25: final | C25: P52A14SE | D25: Rainfed | E25: 2 | F25: 24 | G25: 45576 | H25: 284 | J25: sarec | K25: 37100 | L25: 0 | M25: 2.6 | N25: 33.89 | O25: 98.3 | P25: 66 | Q25: 229 | R25: 200.79 | S25: 490.5 | T25: 3420.6236 | U25: 2 | V25: 0.914 | W25: 1.828 | X25: 0 | Y25: 65.981315 | Z25: 860.04106 | AA25: 2494.6013 | AB25: 1674.9103 | AC25: 1596.9884 | AD25: 1613.7856 | AF25: 0.47178109 | AG25: 27.638396 | AH25: 51.816 | AI25: 13.4
A26: 2024 | B26: final | C26: P48A14E | D26: Rainfed | E26: 3 | F26: 25 | G26: 45566 | H26: 274 | J26: sarec | K26: 37100 | L26: 0 | M26: 0 | N26: 23.89 | O26: 96.3 | P26: 63.6 | Q26: 264.8 | R26: 183.79 | S26: 557.5 | T26: 3707.2757 | U26: 2 | V26: 0.914 | W26: 1.828 | X26: 0 | Y26: 0 | Z26: 736.89006 | AA26: 2970.3856 | AB26: 1961.75 | AC26: 1760.8728 | AD26: 1796.4989 | AF26: 0.48458735 | AG26: 30.767625 | AH26: 50.8 | AI26: 16.6
A27: 2024 | B27: final | C27: P42A84E | D27: Rainfed | E27: 3 | F27: 26 | G27: 45576 | H27: 284 | J27: sarec | K27: 37100 | L27: 0 | M27: 0 | N27: 15.89 | O27: 66.3 | P27: 42.4 | Q27: 256.8 | R27: 124.59 | S27: 573.5 | T27: 3586.9256 | U27: 2 | V27: 0.914 | W27: 1.828 | X27: 0 | Y27: 0 | Z27: 693.46937 | AA27: 2893.4562 | AB27: 1850.4154 | AC27: 1606.1421 | AD27: 1636.7615 | AF27: 0.4563132 | AG27: 28.031892 | AH27: 51.562 | AI27: 14
A28: 2024 | B28: final | C28: R19-45980 | D28: Rainfed | E28: 3 | F28: 27 | G28: 45576 | H28: 284 | J28: sarec | K28: 37100 | L28: 0 | M28: 0 | N28: 0 | O28: 0 | P28: 0 | Q28: 263.7 | R28: 0 | S28: 576.5 | T28: 3153.7199 | U28: 2 | V28: 0.914 | W28: 1.828 | X28: 0 | Y28: 0 | Z28: 0 | AA28: 0 | AB28: 0 | AC28: 1442.5602 | AD28: 1442.5602 | AF28: 0.45741544 | AG28: 24.705916
A29: 2024 | B29: final | C29: PI471938 | D29: Rainfed | E29: 3 | F29: 28 | G29: 45562 | H29: 270 | J29: sarec | K29: 37100 | L29: 0 | M29: 2.6 | N29: 54.89 | O29: 200.3 | P29: 118.9 | Q29: 198.6 | R29: 376.69 | S29: 526.5 | T29: 4290.4267 | U29: 2 | V29: 0.914 | W29: 1.828 | X29: 0 | Y29: 43.27208 | Z29: 913.54017 | AA29: 3333.6144 | AB29: 1978.8655 | AC29: 1618.3832 | AD29: 1736.8709 | AF29: 0.40482475 | AG29: 29.74641 | AH29: 38.354 | AI29: 13.8
A30: 2024 | B30: final | C30: PI507408 | D30: Rainfed | E30: 3 | F30: 29 | G30: 45562 | H30: 270 | J30: sarec | K30: 37100 | L30: 0 | M30: 0 | N30: 0 | O30: 0 | P30: 0 | Q30: 307.3 | R30: 0 | S30: 670.5 | T30: 3667.9431 | U30: 2 | V30: 0.914 | W30: 1.828 | X30: 0 | Y30: 0 | Z30: 0 | AA30: 0 | AB30: 0 | AC30: 1681.0722 | AD30: 1681.0722 | AF30: 0.45831469 | AG30: 28.790777
A31: 2024 | B31: final | C31: PI603457A | D31: Rainfed | E31: 3 | F31: 30 | G31: 45562 | H31: 270 | J31: sarec | K31: 37100 | L31: 0 | M31: 9.6 | N31: 33.89 | O31: 96.3 | P31: 59.4 | Q31: 151.9 | R31: 199.19 | S31: 406.5 | T31: 2988.4573 | U31: 2 | V31: 0.914 | W31: 1.828 | X31: 0 | Y31: 205.23063 | Z31: 724.5069 | AA31: 2058.7198 | AB31: 1269.8645 | AC31: 1116.72 | AD31: 1155.9081 | AF31: 0.3867909 | AG31: 19.796587 | AH31: 39.116 | AI31: 12.6
A32: 2024 | B32: final | C32: PI548431 | D32: Rainfed | E32: 3 | F32: 31 | G32: 45562 | H32: 270 | J32: sarec | K32: 37100 | L32: 0 | M32: 0.6 | N32: 34.89 | O32: 72.3 | P32: 36.7 | Q32: 89.7 | R32: 144.49 | S32: 303.5 | T32: 2249.9453 | U32: 2 | V32: 0.914 | W32: 1.828 | X32: 0 | Y32: 12.524048 | Z32: 728.27341 | AA32: 1509.1478 | AB32: 766.05429 | AC32: 664.97559 | AD32: 691.46608 | AF32: 0.30732573 | AG32: 11.84235 | AH32: 59.436 | AI32: 16.2
A33: 2024 | B33: final | C33: P52A14SE | D33: Rainfed | E33: 3 | F33: 32 | G33: 45576 | H33: 284 | J33: sarec | K33: 37100 | L33: 0 | M33: 0 | N33: 30.89 | O33: 96.3 | P33: 62.6 | Q33: 220.4 | R33: 189.79 | S33: 477.5 | T33: 3307.9322 | U33: 2 | V33: 0.914 | W33: 1.828 | X33: 0 | Y33: 0 | Z33: 803.38096 | AA33: 2504.5512 | AB33: 1628.0883 | AC33: 1526.8445 | AD33: 1548.14 | AF33: 0.4680084 | AG33: 26.514123 | AH33: 46.99 | AI33: 14
A34: 2024 | B34: final | C34: R19C-1012 | D34: Rainfed | E34: 3 | F34: 33 | G34: 45566 | H34: 274 | J34: sarec | K34: 37100 | L34: 0 | M34: 0 | N34: 27.89 | O34: 77.3 | P34: 55.8 | Q34: 391.9 | R34: 160.99 | S34: 827.5 | T34: 5102.2429 | U34: 2 | V34: 0.914 | W34: 1.828 | X34: 0 | Y34: 0 | Z34: 1352.805 | AA34: 3749.4379 | AB34: 2706.58 | AC34: 2416.3976 | AD34: 2449.1247 | AF34: 0.48000944 | AG34: 41.94478 | AH34: 66.294 | AI34: 17.8
A35: 2024 | B35: final | C35: R18C-13665 | D35: Rainfed | E35: 3 | F35: 34 | G35: 45576 | H35: 284 | J35: sarec | K35: 37100 | L35: 0 | M35: 0 | N35: 0 | O35: 0 | P35: 0 | Q35: 350.4 | R35: 0 | S35: 691.5 | T35: 3782.8228 | U35: 2 | V35: 0.914 | W35: 1.828 | X35: 0 | Y35: 0 | Z35: 0 | AA35: 0 | AB35: 0 | AC35: 1916.849 | AD35: 1916.849 | AF35: 0.50672451 | AG35: 32.828793
A36: 2024 | B36: final | C36: R18-14502 | D36: Rainfed | E36: 3 | F36: 35 | G36: 45566 | H36: 274 | J36: sarec | K36: 37100 | L36: 0 | M36: 0 | N36: 49.89 | O36: 144.3 | P36: 96.1 | Q36: 282.5 | R36: 290.29 | S36: 684.5 | T36: 4806.8381 | U36: 2 | V36: 0.914 | W36: 1.828 | X36: 0 | Y36: 0 | Z36: 1234.9408 | AA36: 3571.8973 | AB36: 2378.7895 | AC36: 1983.8302 | AD36: 2071.116 | AF36: 0.43086868 | AG36: 35.470837 | AH36: 63.246 | AI36: 20.2
A37: 2024 | B37: final | C37: R19-46252 | D37: Rainfed | E37: 3 | F37: 36 | G37: 45576 | H37: 284 | J37: sarec | K37: 37100 | L37: 0 | M37: 0 | N37: 0 | O37: 0 | P37: 0 | Q37: 340.2 | R37: 0 | S37: 760.5 | T37: 4160.2845 | U37: 2 | V37: 0.914 | W37: 1.828 | X37: 0 | Y37: 0 | Z37: 0 | AA37: 0 | AB37: 0 | AC37: 1861.0503 | AD37: 1861.0503 | AF37: 0.44733728 | AG37: 31.873161
A38: 2024 | B38: final | C38: P42A84E | D38: Irrigated | E38: 1 | F38: 37 | G38: 45579 | H38: 287 | J38: sarec | K38: 37100 | L38: 0.3 | M38: 0 | N38: 52.89 | O38: 134.3 | P38: 97.2 | Q38: 584.6 | R38: 284.69 | S38: 1285.5 | T38: 8057.9322 | U38: 2 | V38: 0.914 | W38: 1.828 | X38: 12.893379 | Y38: 0 | Z38: 2273.1027 | AA38: 5771.936 | AB38: 4177.4548 | AC38: 3664.463 | AD38: 3729.7593 | AF38: 0.46286804 | AG38: 63.877487 | AH38: 78.232 | AI38: 18.2
A39: 2024 | B39: final | C39: P48A14E | D39: Irrigated | E39: 1 | F39: 38 | G39: 45582 | H39: 290 | J39: sarec | K39: 37100 | L39: 0 | M39: 0 | N39: 68.89 | O39: 217.3 | P39: 163.8 | Q39: 851.1 | R39: 449.99 | S39: 1708.5 | T39: 10911.871 | U39: 2 | V39: 0.914 | W39: 1.828 | X39: 0 | Y39: 0 | Z39: 2626.6424 | AA39: 8285.2285 | AB39: 6245.377 | AC39: 5435.817 | AD39: 5551.9694 | AF39: 0.50880087 | AG39: 95.085452 | AH39: 91.948 | AI39: 20.6
A40: 2024 | B40: final | C40: P52A14SE | D40: Irrigated | E40: 1 | F40: 39 | G40: 45582 | H40: 290 | J40: sarec | K40: 37100 | L40: 0 | M40: 0 | N40: 63.89 | O40: 160.3 | P40: 120.5 | Q40: 539.8 | R40: 344.69 | S40: 1126.5 | T40: 7388.895 | U40: 2 | V40: 0.914 | W40: 1.828 | X40: 0 | Y40: 0 | Z40: 2105.6983 | AA40: 5283.1967 | AB40: 3971.461 | AC40: 3540.6352 | AD40: 3612.1444 | AF40: 0.48886125 | AG40: 61.863163 | AH40: 59.436 | AI40: 14.2
...

Sheet %reduction
F1: average | I1: reduction | O1: AVERAGE | R1: reduction
B2: 2025 | C2: irrigated | D2: biomass | E2: =+AVERAGE('all mm'!R470:R634) -> 6599.0537 | F2: 5030.8134 | H2: =+(F2-F3)/F2 -> 0.36605124 | I2: =+H2 -> 0.36605124 | K2: 2025 | L2: irrigated | M2: yield | N2: =+AVERAGE('all mm'!AB470:AB634) -> 3426.3769 | O2: 3587.0632 | Q2: =+(O2-O3)/O2 -> 0.57337244 | R2: =+Q2 -> 0.57337244
B3: 2025 | C3: ranfed | D3: biomass | E3: =+AVERAGE('all mm'!R635:R660) -> 3068.6399 | F3: 3189.2779 | K3: 2025 | L3: ranfed | M3: yield | N3: =+AVERAGE('all mm'!AB635:AB660) -> 1468.5017 | O3: 1530.34
B4: 2024 | C4: irrigated | D4: biomass | E4: =+AVERAGE('all mm'!R2:R136) -> 1922.8882 | F4: 5771.8935 | H4: =+(F4-F5)/F4 -> 0.24787651 | I4: =+H4 -> 0.24787651 | K4: 2024 | L4: irrigated | M4: yield | N4: =+AVERAGE('all mm'!AB2:AB136) -> #DIV/0! | O4: 3479.2214 | Q4: =+(O4-O5)/O4 -> 0.5634423 | R4: =+Q4 -> 0.5634423
B5: 2024 | C5: rainfed | D5: biomass | E5: =+AVERAGE('all mm'!R138:R468) -> 5218.1707 | F5: 4341.1767 | K5: 2024 | L5: rainfed | M5: yield | N5: =+AVERAGE('all mm'!AB138:AB468) -> 2593.862 | O5: 1518.8809

Sheet 2024-selected
C6: Rainfed | I6: Irrigated
C8: Plot number
A10: Range 12 | B10: REP1 | C10: 12 | D10: REP2 | E10: 24 | F10: REP3 | G10: 36 | H10: REP1 | I10: 48 | J10: REP2 | K10: 60 | L10: REP3 | M10: 72
A11: Range 11 | C11: 11 | E11: 23 | G11: 35 | I11: 47 | K11: 59 | M11: 71
A12: Range 10 | C12: 10 | E12: 22 | G12: 34 | I12: 46 | K12: 58 | M12: 70
A13: Range 9 | C13: 9 | E13: 21 | G13: 33 | I13: 45 | K13: 57 | M13: 69
A14: Range 8 | C14: 8 | E14: 20 | G14: 32 | I14: 44 | K14: 56 | M14: 68
A15: Range 7 | C15: 7 | E15: 19 | G15: 31 | I15: 43 | K15: 55 | M15: 67
A16: Range 6 | C16: 6 | E16: 18 | G16: 30 | I16: 42 | K16: 54 | M16: 66
A17: Range 5 | C17: 5 | E17: 17 | G17: 29 | I17: 41 | K17: 53 | M17: 65
A18: Range 4 | C18: 4 | E18: 16 | G18: 28 | I18: 40 | K18: 52 | M18: 64
A19: Range 3 | C19: 3 | E19: 15 | G19: 27 | I19: 39 | K19: 51 | M19: 63
A20: Range 2 | C20: 2 | E20: 14 | G20: 26 | I20: 38 | K20: 50 | M20: 62
A21: Range 1 | C21: 1 | E21: 13 | G21: 25 | I21: 37 | K21: 49 | M21: 61
P22: PLOT 40 | Q22: H2-H3-H4
C23: Col 1 | E23: Col 2 | G23: Col 3 | I23: Col 4 | K23: Col 5 | M23: Col 6
A34: Rainfed
A36: Range 12 | C36: REP1 | D36: 12 | E36: PI567488B | F36: REP2 | G36: 24 | H36: P52A14SE | I36: REP3 | J36: 36 | K36: R19-46252
A37: Range 11 | D37: 11 | E37: PI424397 | G37: 23 | H37: R18C-13665 | J37: 35 | K37: R18-14502
A38: Range 10 | D38: 10 | E38: PI377574 | G38: 22 | H38: PI567488B | J38: 34 | K38: R18C-13665
A39: Range 9 | D39: 9 | E39: PI398245 | G39: 21 | H39: P42A84E | J39: 33 | K39: R19C-1012
A40: Range 8 | D40: 8 | E40: R19-45980 | G40: 20 | H40: PI424397 | J40: 32 | K40: P52A14SE | M40: R19C-1012 | N40: 4-Early
A41: Range 7 | D41: 7 | E41: R19-46252 | G41: 19 | H41: R18-14502 | J41: 31 | K41: PI377574 | M41: PI377574
A42: Range 6 | D42: 6 | E42: R18C-13665 | G42: 18 | H42: R19C-1012 | J42: 30 | K42: PI424397 | M42: PI398245
A43: Range 5 | D43: 5 | E43: R18-14502 | G43: 17 | H43: R19-46252 | J43: 29 | K43: PI567488B
A44: Range 4 | D44: 4 | E44: R19C-1012 | G44: 16 | H44: P48A14E | J44: 28 | K44: PI398245
A45: Range 3 | D45: 3 | E45: P52A14SE | G45: 15 | H45: PI398245 | J45: 27 | K45: R19-45980 | M45: P42A84E | N45: SOLO EN DOS REP
A46: Range 2 | D46: 2 | E46: P48A14E | G46: 14 | H46: R19-45980 | J46: 26 | K46: P42A84E
A47: Range 1 | D47: 1 | E47: P42A84E | G47: 13 | H47: PI377574 | J47: 25 | K47: P48A14E
R48: 45428 | S48: plantin date rohwer
D49: Col 1 | G49: Col 2 | J49: Col 3 | R49: 45429 | S49: planting date pinetree
A51: Irrigated
A53: Range 12 | C53: REP1 | D53: 48 | E53: PI567488B | F53: REP2 | G53: 60 | H53: P52A14SE | I53: REP3 | J53: 72 | K53: R19-46252
A54: Range 11 | D54: 47 | E54: PI424397 | G54: 59 | H54: R18C-13665 | J54: 71 | K54: R18-14502
A55: Range 10 | D55: 46 | E55: PI377574 | G55: 58 | H55: PI567488B | J55: 70 | K55: R18C-13665
A56: Range 9 | D56: 45 | E56: PI398245 | G56: 57 | H56: P42A84E | J56: 69 | K56: R19C-1012 | M56: R19C-1012
A57: Range 8 | D57: 44 | E57: R19-45980 | G57: 56 | H57: PI424397 | J57: 68 | K57: P52A14SE | M57: PI398245
A58: Range 7 | D58: 43 | E58: R19-46252 | G58: 55 | H58: R18-14502 | J58: 67 | K58: PI377574
A59: Range 6 | D59: 42 | E59: R18C-13665 | G59: 54 | H59: R19C-1012 | J59: 66 | K59: PI424397 | M59: PI377574 | N59: SOLO EN DOS REP
A60: Range 5 | D60: 41 | E60: R18-14502 | G60: 53 | H60: R19-46252 | J60: 65 | K60: PI567488B | M60: P42A84E | N60: 1 REP
...

Sheet interaction_plots
C2: Genotype | D2: behavior
C3: P42A84E | D3: sensible
C4: P48A14E | D4: sensible
C5: P52A14SE | D5: sensible
C6: R19C-1012 | D6: stable for 2024/sensible in 2025
C7: R18-14502 | D7: sensible/higher in rainfed in 2024/high and stable
C8: R18C-13665 | D8: stable
C9: R19-46252 | D9: stable in 2024/sensible in 2025
C10: R19-45980 | D10: sensible in 2024/ stable in 2025
C11: PI471938 | D11: sensible
C12: PI548431 | D12: sensible
C13: PI603457A | D13: sensible
C14: PI507408 | D14: stable

Sheet all mm
A1: Year | B1: Harvest | C1: Genotype | D1: Treatment | E1: Rep | F1: Range | G1: Column | H1: Plot | I1: Date | J1: DOY | K1: DAP | L1: Location | M1: Population | N1: SeedTB_g | O1: SeedTB | P1: BiomassPartition5 | Q1: Biomass_linear | R1: TotalBiomass_kg_ha | S1: linear | T1: RowSpace | U1: TotalSampleArea | V1: GreenBiomass | W1: YellowBiomass | X1: StemBiomass | Y1: ReprodBiomass | Z1: SeedBiomass | AA1: SeedTB_ha | AB1: yield_kg_ha | AC1: yield_combine | AD1: HI | AE1: yield_bu_ac | AF1: AvgHeight | AG1: AvgNode
A2: 2024 | B2: 1 | C2: R18C-13665 | D2: Irrigated | E2: 1 | H2: 6 | I2: 45483 | J2: 191 | K2: =+I2-'2024-selected'!$R$49 -> 54 | L2: pinetree | M2: 37100 | P2: 0.03936 | Q2: 0.08769 | R2: 1316.5803 | S2: 1 | T2: 0.965 | U2: =T2*S2 -> 0.965 | V2: 635.54436 | X2: 681.03595 | AF2: 38.1 | AG2: 12
A3: 2024 | B3: 1 | C3: P52A14SE | D3: Irrigated | E3: 1 | H3: 3 | I3: 45483 | J3: 191 | K3: =+I3-'2024-selected'!$R$49 -> 54 | L3: pinetree | M3: 37100 | P3: 0.03396 | Q3: 0.08919 | R3: 1276.1658 | S3: 1 | T3: 0.965 | U3: =T3*S3 -> 0.965 | V3: 653.86587 | X3: 622.29993 | AF3: 30.226 | AG3: 11.8
A4: 2024 | B4: 1 | C4: R18-14502 | D4: Irrigated | E4: 1 | H4: 5 | I4: 45483 | J4: 191 | K4: =+I4-'2024-selected'!$R$49 -> 54 | L4: pinetree | M4: 37100 | P4: 0.05106 | Q4: 0.11209 | R4: 1690.6736 | S4: 1 | T4: 0.965 | U4: =T4*S4 -> 0.965 | V4: 794.67618 | X4: 895.99739 | AF4: 42.164 | AG4: 12.6
A5: 2024 | B5: 1 | C5: R19-45980 | D5: Irrigated | E5: 1 | H5: 8 | I5: 45483 | J5: 191 | K5: =+I5-'2024-selected'!$R$49 -> 54 | L5: pinetree | M5: 37100 | P5: 0.05416 | Q5: 0.11149 | R5: 1716.5803 | S5: 1 | T5: 0.965 | U5: =T5*S5 -> 0.965 | V5: 805.0432 | X5: 911.53711 | AF5: 57.658 | AG5: 14.4
A6: 2024 | B6: 1 | C6: P42A84E | D6: Irrigated | E6: 1 | H6: 1 | I6: 45483 | J6: 191 | K6: =+I6-'2024-selected'!$R$49 -> 54 | L6: pinetree | M6: 37100 | P6: 0.06286 | Q6: 0.12899 | R6: 1988.0829 | S6: 1 | T6: 0.965 | U6: =T6*S6 -> 0.965 | V6: 948.81462 | X6: 1039.2683 | AF6: 0 | AG6: 12.8 | AH6: 142
A7: 2024 | B7: 1 | C7: R19-46252 | D7: Irrigated | E7: 1 | H7: 7 | I7: 45483 | J7: 191 | K7: =+I7-'2024-selected'!$R$49 -> 54 | L7: pinetree | M7: 37100 | P7: 0.03036 | Q7: 0.13959 | R7: 1761.1399 | S7: 1 | T7: 0.965 | U7: =T7*S7 -> 0.965 | V7: 875.92926 | X7: 885.21063 | AF7: 40.64 | AG7: 13.8
A8: 2024 | B8: 1 | C8: P48A14E | D8: Irrigated | E8: 1 | H8: 2 | I8: 45483 | J8: 191 | K8: =+I8-'2024-selected'!$R$49 -> 54 | L8: pinetree | M8: 37100 | P8: 0.03506 | Q8: 0.17349 | R8: 2161.1399 | S8: 1 | T8: 0.965 | U8: =T8*S8 -> 0.965 | V8: 1010.9154 | X8: 1150.2245 | AF8: 41.656 | AG8: 12
A9: 2024 | B9: 1 | C9: R19C-1012 | D9: Irrigated | E9: 1 | H9: 4 | I9: 45483 | J9: 191 | K9: =+I9-'2024-selected'!$R$49 -> 54 | L9: pinetree | M9: 37100 | P9: 0.04696 | Q9: 0.10169 | R9: 1540.4145 | S9: 1 | T9: 0.965 | U9: =T9*S9 -> 0.965 | V9: 715.09873 | X9: 825.31578 | AF9: 48.514 | AG9: 14.8
A10: 2024 | B10: 1 | C10: R18-14502 | D10: Irrigated | E10: 2 | H10: 15 | I10: 45483 | J10: 191 | K10: =+I10-'2024-selected'!$R$49 -> 54 | L10: pinetree | M10: 37100 | P10: 0.05566 | Q10: 0.06709 | R10: 1272.0207 | S10: 1 | T10: 0.965 | U10: =T10*S10 -> 0.965 | V10: 603.32999 | X10: 668.69074 | AF10: 44.704 | AG10: 14
A11: 2024 | B11: 1 | C11: P52A14SE | D11: Irrigated | E11: 2 | H11: 12 | I11: 45483 | J11: 191 | K11: =+I11-'2024-selected'!$R$49 -> 54 | L11: pinetree | M11: 37100 | P11: 0.04936 | Q11: 0.07459 | R11: 1284.456 | S11: 1 | T11: 0.965 | U11: =T11*S11 -> 0.965 | V11: 606.31734 | X11: 667.72974 | AF11: 38.862 | AG11: 14.4
A12: 2024 | B12: 1 | C12: R18C-13665 | D12: Irrigated | E12: 2 | H12: 13 | I12: 45483 | J12: 191 | K12: =+I12-'2024-selected'!$R$49 -> 54 | L12: pinetree | M12: 37100 | P12: 0.03676 | Q12: 0.11439 | R12: 1566.3212 | S12: 1 | T12: 0.965 | U12: =T12*S12 -> 0.965 | V12: 741.40342 | X12: 824.91783 | AF12: 40.132 | AG12: 13.6
A13: 2024 | B13: 1 | C13: P42A84E | D13: Irrigated | E13: 2 | H13: 14 | I13: 45483 | J13: 191 | K13: =+I13-'2024-selected'!$R$49 -> 54 | L13: pinetree | M13: 37100 | P13: 0.03926 | Q13: 0.11139 | R13: 1561.1399 | S13: 1 | T13: 0.965 | U13: =T13*S13 -> 0.965 | V13: 755.51854 | X13: 805.62135 | AF13: 39.624 | AG13: 13.6
A14: 2024 | B14: 1 | C14: R19-45980 | D14: Irrigated | E14: 2 | H14: 10 | I14: 45483 | J14: 191 | K14: =+I14-'2024-selected'!$R$49 -> 54 | L14: pinetree | M14: 37100 | P14: 0.05946 | Q14: 0.12549 | R14: 1916.5803 | S14: 1 | T14: 0.965 | U14: =T14*S14 -> 0.965 | V14: 889.63365 | X14: 1026.9467 | AF14: 53.594 | AG14: 13.2
A15: 2024 | B15: 1 | C15: R19C-1012 | D15: Irrigated | E15: 2 | H15: 16 | I15: 45483 | J15: 191 | K15: =+I15-'2024-selected'!$R$49 -> 54 | L15: pinetree | M15: 37100 | P15: 0.03556 | Q15: 0.07299 | R15: 1124.8705 | S15: 1 | T15: 0.965 | U15: =T15*S15 -> 0.965 | V15: 534.59817 | X15: 590.2723 | AF15: 37.592 | AG15: 10.8
A16: 2024 | B16: 1 | C16: R19-46252 | D16: Irrigated | E16: 2 | H16: 11 | I16: 45483 | J16: 191 | K16: =+I16-'2024-selected'!$R$49 -> 54 | L16: pinetree | M16: 37100 | P16: 0.04206 | Q16: 0.16549 | R16: 2150.7772 | S16: 1 | T16: 0.965 | U16: =T16*S16 -> 0.965 | V16: 1043.173 | X16: 1107.6042 | AF16: 40.894 | AG16: 11.6
A17: 2024 | B17: 1 | C17: P48A14E | D17: Irrigated | E17: 2 | H17: 9 | I17: 45483 | J17: 191 | K17: =+I17-'2024-selected'!$R$49 -> 54 | L17: pinetree | M17: 37100 | P17: 0.04356 | Q17: 0.23229 | R17: 2858.5492 | S17: 1 | T17: 0.965 | U17: =T17*S17 -> 0.965 | V17: 1338.7145 | X17: 1519.8347 | AF17: 41.91 | AG17: 12.2
A18: 2024 | B18: 1 | C18: P52A14SE | D18: Irrigated | E18: 3 | H18: 24 | I18: 45483 | J18: 191 | K18: =+I18-'2024-selected'!$R$49 -> 54 | L18: pinetree | M18: 37100 | P18: 0.03066 | Q18: 0.07909 | R18: 1137.3057 | S18: 1 | T18: 0.965 | U18: =T18*S18 -> 0.965 | V18: 478.51414 | X18: 658.79156 | AF18: 40.386 | AG18: 12.4
... A25: 2024 | B25: 1 | C25: R19C-1012 | D25: Irrigated | E25: 3 | H25: 19 | I25: 45483 | J25: 191 | K25: =+I25-'2024-selected'!$R$49 -> 54 | L25: pinetree | M25: 37100 | P25: 0.04716 | Q25: 0.20849 | R25: 2649.2228 | S25: 1 | T25: 0.965 | U25: =T25*S25 -> 0.965 | V25: 1230.237 | X25: 1418.9857 | AF25: 49.022 | AG25: 12.6
A26: 2024 | B26: 1 | C26: R19-46252 | D26: Irrigated | E26: 1 | H26: 7 | I26: 45483 | J26: 191 | K26: =+I26-'2024-selected'!$R$48 -> 55 | L26: rohwer | M26: 40800 | P26: 0.04702 | Q26: 0.11598 | R26: 1689.1192 | S26: 1 | T26: 0.965 | U26: =T26*S26 -> 0.965 | V26: 824.8017 | W26: 0 | X26: 1054.7116 | AF26: 37.592 | AG26: 12
A27: 2024 | B27: 1 | C27: P42A84E | D27: Irrigated | E27: 1 | H27: 1 | I27: 45483 | J27: 191 | K27: =+I27-'2024-selected'!$R$48 -> 55 | L27: rohwer | M27: 40800 | S27: 1 | T27: 0.965 | U27: =T27*S27 -> 0.965
A28: 2024 | B28: 1 | C28: R18C-13665 | D28: Irrigated | E28: 1 | H28: 6 | I28: 45483 | J28: 191 | K28: =+I28-'2024-selected'!$R$48 -> 55 | L28: rohwer | M28: 40800 | P28: 0.05492 | Q28: 0.15038 | R28: 2127.4611 | S28: 1 | T28: 0.965 | U28: =T28*S28 -> 0.965 | V28: 990.1294 | W28: 0 | X28: 1606.055 | AF28: 41.148 | AG28: 13.6
A29: 2024 | B29: 1 | C29: R18-14502 | D29: Irrigated | E29: 1 | H29: 5 | I29: 45483 | J29: 191 | K29: =+I29-'2024-selected'!$R$48 -> 55 | L29: rohwer | M29: 40800 | P29: 0.06872 | Q29: 0.18128 | R29: 2590.6736 | S29: 1 | T29: 0.965 | U29: =T29*S29 -> 0.965 | V29: 1027.6741 | W29: 0 | X29: 1747.7245 | AF29: 48.768 | AG29: 14.8
A30: 2024 | B30: 1 | C30: R19-45980 | D30: Irrigated | E30: 1 | H30: 8 | I30: 45483 | J30: 191 | K30: =+I30-'2024-selected'!$R$48 -> 55 | L30: rohwer | M30: 40800 | P30: 0.07992 | Q30: 0.15288 | R30: 2412.4352 | S30: 1 | T30: 0.965 | U30: =T30*S30 -> 0.965 | V30: 1088.4937 | W30: 0 | X30: 726.26616 | AF30: 50.8 | AG30: 12.6
A31: 2024 | B31: 1 | C31: P52A14SE | D31: Irrigated | E31: 1 | H31: 3 | I31: 45483 | J31: 191 | K31: =+I31-'2024-selected'!$R$48 -> 55 | L31: rohwer | M31: 40800 | P31: 0.05682 | Q31: 0.20358 | R31: 2698.4456 | S31: 1 | T31: 0.965 | U31: =T31*S31 -> 0.965 | V31: 1109.3926 | W31: 0 | X31: 1456.0778 | AF31: 42.672 | AG31: 12.2
A32: 2024 | B32: 1 | C32: P48A14E | D32: Irrigated | E32: 1 | H32: 2 | I32: 45483 | J32: 191 | K32: =+I32-'2024-selected'!$R$48 -> 55 | L32: rohwer | M32: 40800 | P32: 0.05552 | Q32: 0.18858 | R32: 2529.5337 | S32: 1 | T32: 0.965 | U32: =T32*S32 -> 0.965 | V32: 1132.6406 | W32: 0 | X32: 0 | AF32: 37.084 | AG32: 12.2
A33: 2024 | B33: 1 | C33: R19C-1012 | D33: Irrigated | E33: 1 | H33: 4 | I33: 45483 | J33: 191 | K33: =+I33-'2024-selected'!$R$48 -> 55 | L33: rohwer | M33: 40800 | P33: 0.07892 | Q33: 0.15628 | R33: 2437.3057 | S33: 1 | T33: 0.965 | U33: =T33*S33 -> 0.965 | V33: 1005.5585 | W33: 6.176649 | X33: 1024.0884 | AF33: 49.784 | AG33: 14.8
A34: 2024 | B34: 1 | C34: P42A84E | D34: Irrigated | E34: 2 | H34: 14 | I34: 45483 | J34: 191 | K34: =+I34-'2024-selected'!$R$48 -> 55 | L34: rohwer | M34: 40800 | S34: 1 | T34: 0.965 | U34: =T34*S34 -> 0.965
A35: 2024 | B35: 1 | C35: P48A14E | D35: Irrigated | E35: 2 | H35: 9 | I35: 45483 | J35: 191 | K35: =+I35-'2024-selected'!$R$48 -> 55 | L35: rohwer | M35: 40800 | P35: 0.04492 | Q35: 0.18698 | R35: 2403.1088 | S35: 1 | T35: 0.965 | U35: =T35*S35 -> 0.965 | V35: 1014.3131 | W35: 0 | X35: 2346.4014 | AF35: 44.196 | AG35: 10.6
A36: 2024 | B36: 1 | C36: R18C-13665 | D36: Irrigated | E36: 2 | H36: 13 | I36: 45483 | J36: 191 | K36: =+I36-'2024-selected'!$R$48 -> 55 | L36: rohwer | M36: 40800 | P36: 0.08352 | Q36: 0.14328 | R36: 2350.2591 | S36: 1 | T36: 0.965 | U36: =T36*S36 -> 0.965 | V36: 1099.1513 | W36: 0 | X36: 1251.1077
A37: 2024 | B37: 1 | C37: P52A14SE | D37: Irrigated | E37: 2 | H37: 12 | I37: 45483 | J37: 191 | K37: =+I37-'2024-selected'!$R$48 -> 55 | L37: rohwer | M37: 40800 | P37: 0.08672 | Q37: 0.17748 | R37: 2737.8238 | S37: 1 | T37: 0.965 | U37: =T37*S37 -> 0.965 | V37: 1160.5443 | W37: 0 | X37: 1577.2795 | AF37: 41.656 | AG37: 13
A38: 2024 | B38: 1 | C38: R19-46252 | D38: Irrigated | E38: 2 | H38: 11 | I38: 45483 | J38: 191 | K38: =+I38-'2024-selected'!$R$48 -> 55 | L38: rohwer | M38: 40800 | P38: 0.07712 | Q38: 0.17208 | R38: 2582.3834 | S38: 1 | T38: 0.965 | U38: =T38*S38 -> 0.965 | V38: 1177.3418 | W38: 0 | X38: 1405.0416 | AF38: 40.64 | AG38: 15.4
A39: 2024 | B39: 1 | C39: R19-45980 | D39: Irrigated | E39: 2 | H39: 10 | I39: 45483 | J39: 191 | K39: =+I39-'2024-selected'!$R$48 -> 55 | L39: rohwer | M39: 40800 | P39: 0.04952 | Q39: 0.20928 | R39: 2681.8653 | S39: 1 | T39: 0.965 | U39: =T39*S39 -> 0.965 | V39: 1221.7868 | W39: 0 | X39: 1460.0785 | AF39: 45.212 | AG39: 13.8
A40: 2024 | B40: 1 | C40: R18-14502 | D40: Irrigated | E40: 2 | H40: 15 | I40: 45483 | J40: 191 | K40: =+I40-'2024-selected'!$R$48 -> 55 | L40: rohwer | M40: 40800 | S40: 1 | T40: 0.965 | U40: =T40*S40 -> 0.965 | AF40: 40.132 | AG40: 11.8
A41: 2024 | B41: 1 | C41: R19C-1012 | D41: Irrigated | E41: 2 | H41: 16 | I41: 45483 | J41: 191 | K41: =+I41-'2024-selected'!$R$48 -> 55 | L41: rohwer | M41: 40800 | S41: 1 | T41: 0.965 | U41: =T41*S41 -> 0.965
A42: 2024 | B42: 1 | C42: P42A84E | D42: Irrigated | E42: 3 | H42: 23 | I42: 45483 | J42: 191 | K42: =+I42-'2024-selected'!$R$48 -> 55 | L42: rohwer | M42: 40800 | P42: 0.03722 | Q42: 0.17138 | R42: 2161.658 | S42: 1 | T42: 0.965 | U42: =T42*S42 -> 0.965 | V42: 1031.4628 | W42: 0 | X42: 1130.1952 | AF42: 37.084 | AG42: 14.4
A43: 2024 | B43: 1 | C43: P48A14E | D43: Irrigated | E43: 3 | H43: 18 | I43: 45483 | J43: 191 | K43: =+I43-'2024-selected'!$R$48 -> 55 | L43: rohwer | M43: 40800 | P43: 0.05712 | Q43: 0.15518 | R43: 2200 | S43: 1 | T43: 0.965 | U43: =T43*S43 -> 0.965 | V43: 880.46218 | W43: 0 | X43: 1319.5378 | AF43: 38.608 | AG43: 11.6
A44: 2024 | B44: 1 | C44: R19-46252 | D44: Irrigated | E44: 3 | H44: 22 | I44: 45483 | J44: 191 | K44: =+I44-'2024-selected'!$R$48 -> 55 | L44: rohwer | M44: 40800 | P44: 0.08232 | Q44: 0.10728 | R44: 1964.7668 | S44: 1 | T44: 0.965 | U44: =T44*S44 -> 0.965 | V44: 1008.6376 | W44: 0 | X44: 956.12925 | AF44: 35.56 | AG44: 13.4
A45: 2024 | B45: 1 | C45: P52A14SE | D45: Irrigated | E45: 3 | H45: 24 | I45: 45483 | J45: 191 | K45: =+I45-'2024-selected'!$R$48 -> 55 | L45: rohwer | M45: 40800 | P45: 0.04802 | Q45: 0.20698 | R45: 2642.487 | S45: 1 | T45: 0.965 | U45: =T45*S45 -> 0.965 | V45: 1037.8448 | W45: 0 | X45: 1604.6423 | AF45: 44.196 | AG45: 11.4
A46: 2024 | B46: 1 | C46: R19-45980 | D46: Irrigated | E46: 3 | H46: 17 | I46: 45483 | J46: 191 | K46: =+I46-'2024-selected'!$R$48 -> 55 | L46: rohwer | M46: 40800 | P46: 0.05242 | Q46: 0.20138 | R46: 2630.0518 | S46: 1 | T46: 0.965 | U46: =T46*S46 -> 0.965 | V46: 1121.8611 | W46: 0 | X46: 1508.1907 | AF46: 47.752 | AG46: 10.2
...

Sheet Sheet3
A1: Year | B1: Harvest | C1: Genotype | D1: Treatment | E1: Rep | F1: Range | G1: Column | H1: Plot | I1: yield

Sheet relative-yield
A1: Year | B1: Harvest | C1: Genotype | D1: Treatment | E1: Location | F1: yield_kg_ha | J1: Year | K1: Harvest | L1: Genotype | M1: Treatment | N1: Location | O1: yield_kg_ha
A2: 2024 | B2: 1 | C2: R18C-13665 | D2: Irrigated | E2: pinetree
A3: 2024 | B3: 1 | C3: P52A14SE | D3: Irrigated | E3: pinetree
A4: 2024 | B4: 1 | C4: R18-14502 | D4: Irrigated | E4: pinetree
A5: 2024 | B5: 1 | C5: R19-45980 | D5: Irrigated | E5: pinetree
A6: 2024 | B6: 1 | C6: P42A84E | D6: Irrigated | E6: pinetree | G6: 142
A7: 2024 | B7: 1 | C7: R19-46252 | D7: Irrigated | E7: pinetree
A8: 2024 | B8: 1 | C8: P48A14E | D8: Irrigated | E8: pinetree
A9: 2024 | B9: 1 | C9: R19C-1012 | D9: Irrigated | E9: pinetree
A10: 2024 | B10: 1 | C10: R18-14502 | D10: Irrigated | E10: pinetree
A11: 2024 | B11: 1 | C11: P52A14SE | D11: Irrigated | E11: pinetree
A12: 2024 | B12: 1 | C12: R18C-13665 | D12: Irrigated | E12: pinetree
A13: 2024 | B13: 1 | C13: P42A84E | D13: Irrigated | E13: pinetree
A14: 2024 | B14: 1 | C14: R19-45980 | D14: Irrigated | E14: pinetree
A15: 2024 | B15: 1 | C15: R19C-1012 | D15: Irrigated | E15: pinetree
A16: 2024 | B16: 1 | C16: R19-46252 | D16: Irrigated | E16: pinetree
A17: 2024 | B17: 1 | C17: P48A14E | D17: Irrigated | E17: pinetree
A18: 2024 | B18: 1 | C18: P52A14SE | D18: Irrigated | E18: pinetree
... A313: 2024 | B313: 3 | C313: R19-46252 | D313: Irrigated | E313: sarec
A314: 2025 | B314: final | C314: R19-42848 | D314: Irrigated | E314: sarec | F314: 3095.186 | J314: 2024 | K314: final | L314: R18-14502 | M314: Rainfed | N314: sarec
A315: 2025 | B315: final | C315: R19-42848 | D315: Rainfed | E315: sarec | J315: 2024 | K315: final | L315: R18-14502 | M315: Rainfed | N315: sarec | O315: 1712.2538
A316: 2024 | B316: final | C316: P42A84E | D316: Rainfed | E316: sarec | F316: 1516.9584 | J316: 2024 | K316: final | L316: R18-14502 | M316: Rainfed | N316: sarec | O316: 2071.116
A317: 2024 | B317: final | C317: P42A84E | D317: Rainfed | E317: sarec | F317: 1430.5252 | J317: 2024 | K317: final | L317: R18-14502 | M317: Irrigated | N317: sarec | O317: 2659.7374
A318: 2024 | B318: final | C318: P42A84E | D318: Rainfed | E318: sarec | F318: 1636.7615 | J318: 2024 | K318: final | L318: R18-14502 | M318: Irrigated | N318: sarec | O318: 3208.4245
A319: 2024 | B319: final | C319: P42A84E | D319: Irrigated | E319: sarec | F319: 3729.7593 | J319: 2024 | K319: final | L319: R18-14502 | M319: Irrigated | N319: sarec | O319: 4084.7921
A320: 2024 | B320: final | C320: P42A84E | D320: Irrigated | E320: sarec | F320: 4454.0481 | J320: 2025 | K320: final | L320: R18-14502 | M320: Irrigated | N320: sarec | O320: 4396.0613
A321: 2024 | B321: final | C321: P42A84E | D321: Irrigated | E321: sarec | F321: 4184.9015 | J321: 2025 | K321: final | L321: R18-14502 | M321: Irrigated | N321: sarec | O321: 3795.4048
A322: 2025 | B322: final | C322: P42A84E | D322: Irrigated | E322: sarec | F322: 3667.3961 | J322: 2025 | K322: final | L322: R18-14502 | M322: Irrigated | N322: sarec | O322: 2227.5711
A323: 2025 | B323: final | C323: P42A84E | D323: Irrigated | E323: sarec | F323: 4230.8534 | J323: 2025 | K323: final | L323: R18-14502 | M323: Irrigated | N323: sarec | O323: 3780.0875
A324: 2025 | B324: final | C324: P42A84E | D324: Irrigated | E324: sarec | F324: 4126.9147 | J324: 2025 | K324: final | L324: R18-14502 | M324: Rainfed | N324: sarec | O324: 1944.2013
A325: 2025 | B325: final | C325: P42A84E | D325: Irrigated | E325: sarec | F325: 2943.1072 | J325: 2025 | K325: final | L325: R18-14502 | M325: Rainfed | N325: sarec | O325: 2253.8293
A326: 2025 | B326: final | C326: P42A84E | D326: Rainfed | E326: sarec | J326: 2025 | K326: final | L326: R18-14502 | M326: Rainfed | N326: sarec
A327: 2025 | B327: final | C327: P42A84E | D327: Rainfed | E327: sarec | F327: 1447.4836 | J327: 2025 | K327: final | L327: R18-14502 | M327: Rainfed | N327: sarec | O327: 2461.7068
A328: 2025 | B328: final | C328: P42A84E | D328: Rainfed | E328: sarec | F328: 1075.4923 | J328: 2024 | K328: final | L328: R18C-13665 | M328: Rainfed | N328: sarec | O328: 2586.9803
A329: 2025 | B329: final | C329: P42A84E | D329: Rainfed | E329: sarec | F329: 1323.8512 | J329: 2024 | K329: final | L329: R18C-13665 | M329: Rainfed | N329: sarec | O329: 1802.5164
A330: 2024 | B330: final | C330: P48A14E | D330: Rainfed | E330: sarec | F330: 1449.6718 | J330: 2024 | K330: final | L330: R18C-13665 | M330: Rainfed | N330: sarec | O330: 1916.849
A331: 2024 | B331: final | C331: P48A14E | D331: Rainfed | E331: sarec | F331: 1636.2144 | J331: 2024 | K331: final | L331: R18C-13665 | M331: Irrigated | N331: sarec | O331: 4312.3632
A332: 2024 | B332: final | C332: P48A14E | D332: Rainfed | E332: sarec | F332: 1796.4989 | J332: 2024 | K332: final | L332: R18C-13665 | M332: Irrigated | N332: sarec | O332: 3689.2779
A333: 2024 | B333: final | C333: P48A14E | D333: Irrigated | E333: sarec | F333: 5551.9694 | J333: 2024 | K333: final | L333: R18C-13665 | M333: Irrigated | N333: sarec | O333: 3602.2976
A334: 2024 | B334: final | C334: P48A14E | D334: Irrigated | E334: sarec | F334: 4379.1028 | J334: 2025 | K334: final | L334: R18C-13665 | M334: Irrigated | N334: sarec | O334: 2908.0963
...

Sheet relative_yield
A1: Year | B1: Harvest | C1: Genotype | D1: Yield_Irrig | E1: Yield_rainfed | F1: Relative_yield | I1: Year | J1: Harvest | K1: Genotype | L1: Yield_Irrig | M1: Yield_rainfed | N1: Relative_yield
A2: 2025 | B2: final | C2: R19-42848 | D2: 3095.186 | F2: =+D2-E2 -> 3095.186 | I2: 2025 | J2: final | K2: R18-14502 | L2: 3549.7812 | M2: 2219.9125 | N2: 1329.8687
A3: 2024 | B3: final | C3: P42A84E | D3: =+AVERAGE('relative-yield'!$F$319:$F$321) -> 4122.903 | E3: =+AVERAGE('relative-yield'!$F$316:$F$318) -> 1528.0817 | F3: =+D3-E3 -> 2594.8213 | I3: 2024 | J3: final | K3: R18-14502 | L3: 3317.6513 | M3: 1891.6849 | N3: 1425.9664
A4: 2025 | B4: final | C4: P42A84E | D4: =+AVERAGE('relative-yield'!$F$322:$F$325) -> 3742.0678 | E4: =+AVERAGE('relative-yield'!$F$327:$F$329) -> 1282.2757 | F4: =+D4-E4 -> 2459.7921 | I4: 2024 | J4: final | K4: PI507408 | L4: 3297.4106 | M4: 1664.1138 | N4: 1633.2969
A5: 2024 | B5: final | C5: P48A14E | D5: =+AVERAGE('relative-yield'!$F$333:$F$335) -> 4861.2327 | E5: =+AVERAGE('relative-yield'!$F$330:$F$332) -> 1627.4617 | F5: =+D5-E5 -> 3233.771 | I5: 2024 | J5: final | K5: PI548431 | L5: 2442.5602 | M5: 711.34209 | N5: 1731.2181
A6: 2025 | B6: final | C6: P48A14E | D6: =+AVERAGE('relative-yield'!$F$336:$F$339) -> 4756.8381 | E6: =+AVERAGE('relative-yield'!$F$340:$F$343) -> 1576.5864 | F6: =+D6-E6 -> 3180.2516 | I6: 2024 | J6: final | K6: PI471938 | L6: 3106.4916 | M6: 1350.1094 | N6: 1756.3822
A7: 2024 | B7: final | C7: P52A14SE | D7: =+AVERAGE('relative-yield'!$F$347:$F$349) -> 3739.2414 | E7: =+AVERAGE('relative-yield'!$F$344:$F$346) -> 1494.3472 | F7: =+D7-E7 -> 2244.8942 | I7: 2024 | J7: final | K7: R18C-13665 | L7: 3867.9796 | M7: 2102.1152 | N7: 1765.8643
A8: 2025 | B8: final | C8: P52A14SE | D8: =+AVERAGE('relative-yield'!$F$350:$F$353) -> 3169.3107 | E8: =+AVERAGE('relative-yield'!$F$354:$F$357) -> 1391.6849 | F8: =+D8-E8 -> 1777.6258 | I8: 2025 | J8: final | K8: P52A14SE | L8: 3169.3107 | M8: 1391.6849 | N8: 1777.6258
A9: 2024 | B9: final | C9: PI471938 | D9: =+AVERAGE('relative-yield'!$F$361:$F$363) -> 3106.4916 | E9: =+AVERAGE('relative-yield'!$F$358:$F$360) -> 1350.1094 | F9: =+D9-E9 -> 1756.3822 | I9: 2024 | J9: final | K9: R19-46252 | L9: 3469.5478 | M9: 1690.372 | N9: 1779.1758
A10: 2024 | B10: final | C10: PI507408 | D10: =+AVERAGE('relative-yield'!$F$367:$F$369) -> 3297.4106 | E10: =+AVERAGE('relative-yield'!$F$364:$F$366) -> 1664.1138 | F10: =+D10-E10 -> 1633.2969 | I10: 2025 | J10: final | K10: R18C-13665 | L10: 3224.5624 | M10: 1399.3435 | N10: 1825.2188
A11: 2024 | B11: final | C11: PI548431 | D11: =+'relative-yield'!$F$375 -> 2442.5602 | E11: =+AVERAGE('relative-yield'!$F$370:$F$372) -> 711.34209 | F11: =+D11-E11 -> 1731.2181 | I11: 2025 | J11: final | K11: R19-45980 | L11: 3381.291 | M11: 1554.3399 | N11: 1826.9511
A12: 2024 | B12: final | C12: PI603457A | D12: =+AVERAGE('relative-yield'!$F$379:$F$381) -> 2865.4267 | E12: =+AVERAGE('relative-yield'!$F$376:$F$378) -> 987.23559 | F12: =+D12-E12 -> 1878.1911 | I12: 2024 | J12: final | K12: PI603457A | L12: 2865.4267 | M12: 987.23559 | N12: 1878.1911
A13: 2024 | B13: final | C13: R18-14502 | D13: =+AVERAGE('relative-yield'!$O$317:$O$319) -> 3317.6513 | E13: =+AVERAGE('relative-yield'!$O$314:$O$316) -> 1891.6849 | F13: =+D13-E13 -> 1425.9664 | I13: 2024 | J13: final | K13: R19C-1012 | L13: 3868.5266 | M13: 1861.415 | N13: 2007.1116
A14: 2025 | B14: final | C14: R18-14502 | D14: =+AVERAGE('relative-yield'!$O$320:$O$323) -> 3549.7812 | E14: =+AVERAGE('relative-yield'!$O$324:$O$327) -> 2219.9125 | F14: =+D14-E14 -> 1329.8687 | I14: 2025 | J14: final | K14: R19C-1012 | L14: 3388.1291 | M14: 1347.1918 | N14: 2040.9373
A15: 2024 | B15: final | C15: R18C-13665 | D15: =+AVERAGE('relative-yield'!$O$331:$O$333) -> 3867.9796 | E15: =+AVERAGE('relative-yield'!$O$328:$O$330) -> 2102.1152 | F15: =+D15-E15 -> 1765.8643 | I15: 2025 | J15: final | K15: R19-46252 | L15: 3607.4945 | M15: 1565.0985 | N15: 2042.3961
A16: 2025 | B16: final | C16: R18C-13665 | D16: =+AVERAGE('relative-yield'!$O$334:$O$337) -> 3224.5624 | E16: =+AVERAGE('relative-yield'!$O$338:$O$341) -> 1399.3435 | F16: =+D16-E16 -> 1825.2188 | I16: 2024 | J16: final | K16: P52A14SE | L16: 3739.2414 | M16: 1494.3472 | N16: 2244.8942
A17: 2024 | B17: final | C17: R19-45980 | D17: =+AVERAGE('relative-yield'!$O$345:$O$347) -> 4607.9504 | E17: =+AVERAGE('relative-yield'!$O$342:$O$344) -> 1442.5602 | F17: =+D17-E17 -> 3165.3902 | I17: 2025 | J17: final | K17: P42A84E | L17: 3742.0678 | M17: 1282.2757 | N17: 2459.7921
A18: 2025 | B18: final | C18: R19-45980 | D18: =+AVERAGE('relative-yield'!$O$348:$O$351) -> 3381.291 | E18: =+AVERAGE('relative-yield'!$O$352:$O$355) -> 1554.3399 | F18: =+D18-E18 -> 1826.9511 | I18: 2024 | J18: final | K18: P42A84E | L18: 4122.903 | M18: 1528.0817 | N18: 2594.8213
A19: 2024 | B19: final | C19: R19-46252 | D19: =+AVERAGE('relative-yield'!$O$359:$O$361) -> 3469.5478 | E19: =+AVERAGE('relative-yield'!$O$356:$O$358) -> 1690.372 | F19: =+D19-E19 -> 1779.1758 | I19: 2025 | J19: final | K19: R19-42848 | L19: 3095.186 | N19: 3095.186
A20: 2025 | B20: final | C20: R19-46252 | D20: =+AVERAGE('relative-yield'!$O$362:$O$365) -> 3607.4945 | E20: =+AVERAGE('relative-yield'!$O$366:$O$369) -> 1565.0985 | F20: =+D20-E20 -> 2042.3961 | I20: 2024 | J20: final | K20: R19-45980 | L20: 4607.9504 | M20: 1442.5602 | N20: 3165.3902
A21: 2024 | B21: final | C21: R19C-1012 | D21: =+AVERAGE('relative-yield'!$O$373:$O$375) -> 3868.5266 | E21: =+AVERAGE('relative-yield'!$O$370:$O$372) -> 1861.415 | F21: =+D21-E21 -> 2007.1116 | I21: 2025 | J21: final | K21: P48A14E | L21: 4756.8381 | M21: 1576.5864 | N21: 3180.2516
A22: 2025 | B22: final | C22: R19C-1012 | D22: =+AVERAGE('relative-yield'!$O$376:$O$379) -> 3388.1291 | E22: =+AVERAGE('relative-yield'!$O$380:$O$383) -> 1347.1918 | F22: =+D22-E22 -> 2040.9373 | I22: 2024 | J22: final | K22: P48A14E | L22: 4861.2327 | M22: 1627.4617 | N22: 3233.771
